[2023-11-06T03:55:46.536+0000] {taskinstance.py:1103} INFO - Dependencies all met for dep_context=non-requeueable deps ti=<TaskInstance: create_tables_and_copy_csv.create_leh_table manual__2023-11-06T03:55:43.026415+00:00 [queued]>
[2023-11-06T03:55:46.560+0000] {taskinstance.py:1103} INFO - Dependencies all met for dep_context=requeueable deps ti=<TaskInstance: create_tables_and_copy_csv.create_leh_table manual__2023-11-06T03:55:43.026415+00:00 [queued]>
[2023-11-06T03:55:46.561+0000] {taskinstance.py:1308} INFO - Starting attempt 1 of 1
[2023-11-06T03:55:46.594+0000] {taskinstance.py:1327} INFO - Executing <Task(SnowflakeOperator): create_leh_table> on 2023-11-06 03:55:43.026415+00:00
[2023-11-06T03:55:46.606+0000] {standard_task_runner.py:57} INFO - Started process 388 to run task
[2023-11-06T03:55:46.617+0000] {standard_task_runner.py:84} INFO - Running: ['***', 'tasks', 'run', 'create_tables_and_copy_csv', 'create_leh_table', 'manual__2023-11-06T03:55:43.026415+00:00', '--job-id', '68', '--raw', '--subdir', 'DAGS_FOLDER/copy_processed_data_to_snowflake.py', '--cfg-path', '/tmp/tmp6aqrxrqx']
[2023-11-06T03:55:46.625+0000] {standard_task_runner.py:85} INFO - Job 68: Subtask create_leh_table
[2023-11-06T03:55:46.807+0000] {task_command.py:410} INFO - Running <TaskInstance: create_tables_and_copy_csv.create_leh_table manual__2023-11-06T03:55:43.026415+00:00 [running]> on host 0ca024afdc5f
[2023-11-06T03:55:47.181+0000] {taskinstance.py:1547} INFO - Exporting env vars: AIRFLOW_CTX_DAG_OWNER='***' AIRFLOW_CTX_DAG_ID='create_tables_and_copy_csv' AIRFLOW_CTX_TASK_ID='create_leh_table' AIRFLOW_CTX_EXECUTION_DATE='2023-11-06T03:55:43.026415+00:00' AIRFLOW_CTX_TRY_NUMBER='1' AIRFLOW_CTX_DAG_RUN_ID='manual__2023-11-06T03:55:43.026415+00:00'
[2023-11-06T03:55:47.192+0000] {sql.py:265} INFO - Executing: 
        CREATE TABLE IF NOT EXISTS leh (
            /* Define your schema here */
        );
    
[2023-11-06T03:55:47.240+0000] {base.py:73} INFO - Using connection ID 'snowflake_default' for task execution.
[2023-11-06T03:55:47.494+0000] {providers_manager.py:593} WARNING - The connection type 'aws' is already registered in the package 'apache-***-providers-amazon' with different class names: '***.providers.amazon.aws.hooks.base_aws.AwsBaseHook' and '***.providers.amazon.aws.hooks.redshift.RedshiftDataHook'. 
[2023-11-06T03:55:48.209+0000] {warnings.py:110} WARNING - /home/***/.local/lib/python3.7/site-packages/snowflake/connector/options.py:109: UserWarning: You have an incompatible version of 'pyarrow' installed (6.0.1), please install a version that adheres to: 'pyarrow<10.1.0,>=10.0.1; extra == "pandas"'
  "pyarrow", installed_pyarrow_version, pandas_pyarrow_extra

[2023-11-06T03:55:48.594+0000] {base.py:73} INFO - Using connection ID 'snowflake_default' for task execution.
[2023-11-06T03:55:48.596+0000] {connection.py:300} INFO - Snowflake Connector for Python Version: 3.0.4, Python Version: 3.7.13, Platform: Linux-6.4.16-linuxkit-x86_64-with-debian-11.4
[2023-11-06T03:55:48.606+0000] {taskinstance.py:1824} ERROR - Task failed with exception
Traceback (most recent call last):
  File "/home/airflow/.local/lib/python3.7/site-packages/airflow/providers/common/sql/operators/sql.py", line 277, in execute
    **extra_kwargs,
  File "/home/airflow/.local/lib/python3.7/site-packages/airflow/providers/snowflake/hooks/snowflake.py", line 373, in run
    with closing(self.get_conn()) as conn:
  File "/home/airflow/.local/lib/python3.7/site-packages/airflow/providers/snowflake/hooks/snowflake.py", line 296, in get_conn
    conn = connector.connect(**conn_config)
  File "/home/airflow/.local/lib/python3.7/site-packages/snowflake/connector/__init__.py", line 51, in Connect
    return SnowflakeConnection(**kwargs)
  File "/home/airflow/.local/lib/python3.7/site-packages/snowflake/connector/connection.py", line 319, in __init__
    self.connect(**kwargs)
  File "/home/airflow/.local/lib/python3.7/site-packages/snowflake/connector/connection.py", line 562, in connect
    self.__config(**kwargs)
  File "/home/airflow/.local/lib/python3.7/site-packages/snowflake/connector/connection.py", line 1006, in __config
    {"msg": "Account must be specified", "errno": ER_NO_ACCOUNT_NAME},
  File "/home/airflow/.local/lib/python3.7/site-packages/snowflake/connector/errors.py", line 294, in errorhandler_wrapper
    error_value,
  File "/home/airflow/.local/lib/python3.7/site-packages/snowflake/connector/errors.py", line 348, in hand_to_other_handler
    connection.errorhandler(connection, cursor, error_class, error_value)
  File "/home/airflow/.local/lib/python3.7/site-packages/snowflake/connector/errors.py", line 231, in default_errorhandler
    cursor=cursor,
snowflake.connector.errors.ProgrammingError: 251001: 251001: Account must be specified
[2023-11-06T03:55:48.621+0000] {taskinstance.py:1350} INFO - Marking task as FAILED. dag_id=create_tables_and_copy_csv, task_id=create_leh_table, execution_date=20231106T035543, start_date=20231106T035546, end_date=20231106T035548
[2023-11-06T03:55:48.644+0000] {standard_task_runner.py:109} ERROR - Failed to execute job 68 for task create_leh_table (251001: 251001: Account must be specified; 388)
[2023-11-06T03:55:48.689+0000] {local_task_job_runner.py:225} INFO - Task exited with return code 1
[2023-11-06T03:55:48.735+0000] {taskinstance.py:2653} INFO - 0 downstream tasks scheduled from follow-on schedule check
