[2023-11-05 22:35:49,045] {taskinstance.py:1179} INFO - Dependencies all met for <TaskInstance: split_excel_to_s3.read_excel manual__2023-11-05T22:35:46.834002+00:00 [queued]>
[2023-11-05 22:35:49,054] {taskinstance.py:1179} INFO - Dependencies all met for <TaskInstance: split_excel_to_s3.read_excel manual__2023-11-05T22:35:46.834002+00:00 [queued]>
[2023-11-05 22:35:49,055] {taskinstance.py:1376} INFO - 
--------------------------------------------------------------------------------
[2023-11-05 22:35:49,055] {taskinstance.py:1377} INFO - Starting attempt 1 of 2
[2023-11-05 22:35:49,055] {taskinstance.py:1378} INFO - 
--------------------------------------------------------------------------------
[2023-11-05 22:35:49,069] {taskinstance.py:1397} INFO - Executing <Task(PythonOperator): read_excel> on 2023-11-05 22:35:46.834002+00:00
[2023-11-05 22:35:49,075] {standard_task_runner.py:52} INFO - Started process 705 to run task
[2023-11-05 22:35:49,078] {standard_task_runner.py:79} INFO - Running: ['***', 'tasks', 'run', 'split_excel_to_s3', 'read_excel', 'manual__2023-11-05T22:35:46.834002+00:00', '--job-id', '42', '--raw', '--subdir', 'DAGS_FOLDER/write_xlsx_to_csv_s3.py', '--cfg-path', '/tmp/tmpp1kkmxd1', '--error-file', '/tmp/tmpetmz3_be']
[2023-11-05 22:35:49,080] {standard_task_runner.py:80} INFO - Job 42: Subtask read_excel
[2023-11-05 22:35:49,147] {task_command.py:371} INFO - Running <TaskInstance: split_excel_to_s3.read_excel manual__2023-11-05T22:35:46.834002+00:00 [running]> on host c2e2f4edd06f
[2023-11-05 22:35:49,398] {taskinstance.py:1591} INFO - Exporting the following env vars:
AIRFLOW_CTX_DAG_OWNER=***
AIRFLOW_CTX_DAG_ID=split_excel_to_s3
AIRFLOW_CTX_TASK_ID=read_excel
AIRFLOW_CTX_EXECUTION_DATE=2023-11-05T22:35:46.834002+00:00
AIRFLOW_CTX_TRY_NUMBER=1
AIRFLOW_CTX_DAG_RUN_ID=manual__2023-11-05T22:35:46.834002+00:00
[2023-11-05 22:35:49,401] {taskinstance.py:1909} ERROR - Task failed with exception
Traceback (most recent call last):
  File "/home/airflow/.local/lib/python3.7/site-packages/airflow/operators/python.py", line 171, in execute
    return_value = self.execute_callable()
  File "/home/airflow/.local/lib/python3.7/site-packages/airflow/operators/python.py", line 189, in execute_callable
    return self.python_callable(*self.op_args, **self.op_kwargs)
  File "/opt/airflow/dags/write_xlsx_to_csv_s3.py", line 30, in read_excel
    combined_df = pd.concat(dataframes, ignore_index=True)
  File "/home/airflow/.local/lib/python3.7/site-packages/pandas/util/_decorators.py", line 311, in wrapper
    return func(*args, **kwargs)
  File "/home/airflow/.local/lib/python3.7/site-packages/pandas/core/reshape/concat.py", line 304, in concat
    sort=sort,
  File "/home/airflow/.local/lib/python3.7/site-packages/pandas/core/reshape/concat.py", line 351, in __init__
    raise ValueError("No objects to concatenate")
ValueError: No objects to concatenate
[2023-11-05 22:35:49,411] {taskinstance.py:1420} INFO - Marking task as UP_FOR_RETRY. dag_id=split_excel_to_s3, task_id=read_excel, execution_date=20231105T223546, start_date=20231105T223549, end_date=20231105T223549
[2023-11-05 22:35:49,424] {standard_task_runner.py:97} ERROR - Failed to execute job 42 for task read_excel (No objects to concatenate; 705)
[2023-11-05 22:35:49,452] {local_task_job.py:156} INFO - Task exited with return code 1
[2023-11-05 22:35:49,499] {local_task_job.py:273} INFO - 0 downstream tasks scheduled from follow-on schedule check
