[2023-11-07T02:42:33.839+0000] {taskinstance.py:1159} INFO - Dependencies all met for dep_context=non-requeueable deps ti=<TaskInstance: ps_etl.ps_schema_validation manual__2023-11-07T02:42:25.403574+00:00 [queued]>
[2023-11-07T02:42:33.848+0000] {taskinstance.py:1159} INFO - Dependencies all met for dep_context=requeueable deps ti=<TaskInstance: ps_etl.ps_schema_validation manual__2023-11-07T02:42:25.403574+00:00 [queued]>
[2023-11-07T02:42:33.848+0000] {taskinstance.py:1361} INFO - Starting attempt 1 of 1
[2023-11-07T02:42:33.860+0000] {taskinstance.py:1382} INFO - Executing <Task(PythonOperator): ps_schema_validation> on 2023-11-07 02:42:25.403574+00:00
[2023-11-07T02:42:33.865+0000] {standard_task_runner.py:57} INFO - Started process 775 to run task
[2023-11-07T02:42:33.869+0000] {standard_task_runner.py:84} INFO - Running: ['***', 'tasks', 'run', 'ps_etl', 'ps_schema_validation', 'manual__2023-11-07T02:42:25.403574+00:00', '--job-id', '80', '--raw', '--subdir', 'DAGS_FOLDER/ps_etl.py', '--cfg-path', '/tmp/tmpxgvwq4lq']
[2023-11-07T02:42:33.873+0000] {standard_task_runner.py:85} INFO - Job 80: Subtask ps_schema_validation
[2023-11-07T02:42:33.924+0000] {task_command.py:416} INFO - Running <TaskInstance: ps_etl.ps_schema_validation manual__2023-11-07T02:42:25.403574+00:00 [running]> on host d2308b8de1b3
[2023-11-07T02:42:34.010+0000] {taskinstance.py:1662} INFO - Exporting env vars: AIRFLOW_CTX_DAG_OWNER='***' AIRFLOW_CTX_DAG_ID='ps_etl' AIRFLOW_CTX_TASK_ID='ps_schema_validation' AIRFLOW_CTX_EXECUTION_DATE='2023-11-07T02:42:25.403574+00:00' AIRFLOW_CTX_TRY_NUMBER='1' AIRFLOW_CTX_DAG_RUN_ID='manual__2023-11-07T02:42:25.403574+00:00'
[2023-11-07T02:42:34.050+0000] {logging_mixin.py:151} INFO - Errors found. Details are written to error_sv_leh_2023-11-07-02-42-29.csv.
[2023-11-07T02:42:34.051+0000] {taskinstance.py:1937} ERROR - Task failed with exception
Traceback (most recent call last):
  File "/home/airflow/.local/lib/python3.8/site-packages/airflow/operators/python.py", line 192, in execute
    return_value = self.execute_callable()
  File "/home/airflow/.local/lib/python3.8/site-packages/airflow/operators/python.py", line 209, in execute_callable
    return self.python_callable(*self.op_args, **self.op_kwargs)
  File "/opt/airflow/dags/ps_sv.py", line 90, in data_schema_validation
    error_files.append(leh_error_log_path)
NameError: name 'error_files' is not defined
[2023-11-07T02:42:34.060+0000] {taskinstance.py:1400} INFO - Marking task as FAILED. dag_id=ps_etl, task_id=ps_schema_validation, execution_date=20231107T024225, start_date=20231107T024233, end_date=20231107T024234
[2023-11-07T02:42:34.074+0000] {standard_task_runner.py:104} ERROR - Failed to execute job 80 for task ps_schema_validation (name 'error_files' is not defined; 775)
[2023-11-07T02:42:34.123+0000] {local_task_job_runner.py:228} INFO - Task exited with return code 1
[2023-11-07T02:42:34.151+0000] {taskinstance.py:2778} INFO - 0 downstream tasks scheduled from follow-on schedule check
