[2023-11-07T02:46:03.358+0000] {taskinstance.py:1159} INFO - Dependencies all met for dep_context=non-requeueable deps ti=<TaskInstance: ps_etl.ps_transform manual__2023-11-07T02:45:53.695847+00:00 [queued]>
[2023-11-07T02:46:03.367+0000] {taskinstance.py:1159} INFO - Dependencies all met for dep_context=requeueable deps ti=<TaskInstance: ps_etl.ps_transform manual__2023-11-07T02:45:53.695847+00:00 [queued]>
[2023-11-07T02:46:03.368+0000] {taskinstance.py:1361} INFO - Starting attempt 1 of 1
[2023-11-07T02:46:03.379+0000] {taskinstance.py:1382} INFO - Executing <Task(PythonOperator): ps_transform> on 2023-11-07 02:45:53.695847+00:00
[2023-11-07T02:46:03.384+0000] {standard_task_runner.py:57} INFO - Started process 843 to run task
[2023-11-07T02:46:03.388+0000] {standard_task_runner.py:84} INFO - Running: ['***', 'tasks', 'run', 'ps_etl', 'ps_transform', 'manual__2023-11-07T02:45:53.695847+00:00', '--job-id', '83', '--raw', '--subdir', 'DAGS_FOLDER/ps_etl.py', '--cfg-path', '/tmp/tmpvmrjt4cj']
[2023-11-07T02:46:03.392+0000] {standard_task_runner.py:85} INFO - Job 83: Subtask ps_transform
[2023-11-07T02:46:03.438+0000] {task_command.py:416} INFO - Running <TaskInstance: ps_etl.ps_transform manual__2023-11-07T02:45:53.695847+00:00 [running]> on host d2308b8de1b3
[2023-11-07T02:46:03.513+0000] {taskinstance.py:1662} INFO - Exporting env vars: AIRFLOW_CTX_DAG_OWNER='***' AIRFLOW_CTX_DAG_ID='ps_etl' AIRFLOW_CTX_TASK_ID='ps_transform' AIRFLOW_CTX_EXECUTION_DATE='2023-11-07T02:45:53.695847+00:00' AIRFLOW_CTX_TRY_NUMBER='1' AIRFLOW_CTX_DAG_RUN_ID='manual__2023-11-07T02:45:53.695847+00:00'
[2023-11-07T02:46:03.576+0000] {base.py:73} INFO - Using connection ID 'aws_default' for task execution.
[2023-11-07T02:46:03.577+0000] {connection_wrapper.py:340} INFO - AWS Connection (conn_id='aws_default', conn_type='aws') credentials retrieved from login and password.
[2023-11-07T02:46:05.567+0000] {taskinstance.py:1937} ERROR - Task failed with exception
Traceback (most recent call last):
  File "/home/airflow/.local/lib/python3.8/site-packages/airflow/operators/python.py", line 192, in execute
    return_value = self.execute_callable()
  File "/home/airflow/.local/lib/python3.8/site-packages/airflow/operators/python.py", line 209, in execute_callable
    return self.python_callable(*self.op_args, **self.op_kwargs)
  File "/opt/airflow/dags/ps_transform_dq.py", line 201, in transform_data
    s3_hook.load_file(
  File "/home/airflow/.local/lib/python3.8/site-packages/airflow/providers/amazon/aws/hooks/s3.py", line 136, in wrapper
    return func(*bound_args.args, **bound_args.kwargs)
  File "/home/airflow/.local/lib/python3.8/site-packages/airflow/providers/amazon/aws/hooks/s3.py", line 90, in wrapper
    return func(*bound_args.args, **bound_args.kwargs)
  File "/home/airflow/.local/lib/python3.8/site-packages/airflow/providers/amazon/aws/hooks/s3.py", line 1072, in load_file
    client.upload_file(filename, bucket_name, key, ExtraArgs=extra_args, Config=self.transfer_config)
  File "/home/airflow/.local/lib/python3.8/site-packages/boto3/s3/inject.py", line 143, in upload_file
    return transfer.upload_file(
  File "/home/airflow/.local/lib/python3.8/site-packages/boto3/s3/transfer.py", line 292, in upload_file
    future.result()
  File "/home/airflow/.local/lib/python3.8/site-packages/s3transfer/futures.py", line 103, in result
    return self._coordinator.result()
  File "/home/airflow/.local/lib/python3.8/site-packages/s3transfer/futures.py", line 266, in result
    raise self._exception
  File "/home/airflow/.local/lib/python3.8/site-packages/s3transfer/tasks.py", line 269, in _main
    self._submit(transfer_future=transfer_future, **kwargs)
  File "/home/airflow/.local/lib/python3.8/site-packages/s3transfer/upload.py", line 585, in _submit
    upload_input_manager.provide_transfer_size(transfer_future)
  File "/home/airflow/.local/lib/python3.8/site-packages/s3transfer/upload.py", line 244, in provide_transfer_size
    self._osutil.get_file_size(transfer_future.meta.call_args.fileobj)
  File "/home/airflow/.local/lib/python3.8/site-packages/s3transfer/utils.py", line 247, in get_file_size
    return os.path.getsize(filename)
  File "/usr/local/lib/python3.8/genericpath.py", line 50, in getsize
    return os.stat(filename).st_size
FileNotFoundError: [Errno 2] No such file or directory: 'errors_dq_leh_2023-11-07-02-45-55.csv'
[2023-11-07T02:46:05.578+0000] {taskinstance.py:1400} INFO - Marking task as FAILED. dag_id=ps_etl, task_id=ps_transform, execution_date=20231107T024553, start_date=20231107T024603, end_date=20231107T024605
[2023-11-07T02:46:05.590+0000] {standard_task_runner.py:104} ERROR - Failed to execute job 83 for task ps_transform ([Errno 2] No such file or directory: 'errors_dq_leh_2023-11-07-02-45-55.csv'; 843)
[2023-11-07T02:46:05.613+0000] {local_task_job_runner.py:228} INFO - Task exited with return code 1
[2023-11-07T02:46:05.638+0000] {taskinstance.py:2778} INFO - 0 downstream tasks scheduled from follow-on schedule check
