[2023-11-07T18:10:26.548+0000] {taskinstance.py:1159} INFO - Dependencies all met for dep_context=non-requeueable deps ti=<TaskInstance: ps_etl_s3.ps_extract manual__2023-11-07T18:10:24.952592+00:00 [queued]>
[2023-11-07T18:10:26.560+0000] {taskinstance.py:1159} INFO - Dependencies all met for dep_context=requeueable deps ti=<TaskInstance: ps_etl_s3.ps_extract manual__2023-11-07T18:10:24.952592+00:00 [queued]>
[2023-11-07T18:10:26.561+0000] {taskinstance.py:1361} INFO - Starting attempt 1 of 1
[2023-11-07T18:10:26.576+0000] {taskinstance.py:1382} INFO - Executing <Task(PythonOperator): ps_extract> on 2023-11-07 18:10:24.952592+00:00
[2023-11-07T18:10:26.583+0000] {standard_task_runner.py:57} INFO - Started process 1135 to run task
[2023-11-07T18:10:26.588+0000] {standard_task_runner.py:84} INFO - Running: ['***', 'tasks', 'run', 'ps_etl_s3', 'ps_extract', 'manual__2023-11-07T18:10:24.952592+00:00', '--job-id', '154', '--raw', '--subdir', 'DAGS_FOLDER/ps_etl_s3_input.py', '--cfg-path', '/tmp/tmpq5f74_cp']
[2023-11-07T18:10:26.592+0000] {standard_task_runner.py:85} INFO - Job 154: Subtask ps_extract
[2023-11-07T18:10:26.650+0000] {task_command.py:416} INFO - Running <TaskInstance: ps_etl_s3.ps_extract manual__2023-11-07T18:10:24.952592+00:00 [running]> on host 19429b98c313
[2023-11-07T18:10:26.756+0000] {taskinstance.py:1662} INFO - Exporting env vars: AIRFLOW_CTX_DAG_OWNER='***' AIRFLOW_CTX_DAG_ID='ps_etl_s3' AIRFLOW_CTX_TASK_ID='ps_extract' AIRFLOW_CTX_EXECUTION_DATE='2023-11-07T18:10:24.952592+00:00' AIRFLOW_CTX_TRY_NUMBER='1' AIRFLOW_CTX_DAG_RUN_ID='manual__2023-11-07T18:10:24.952592+00:00'
[2023-11-07T18:10:26.769+0000] {base.py:73} INFO - Using connection ID 'aws_default' for task execution.
[2023-11-07T18:10:26.770+0000] {connection_wrapper.py:340} INFO - AWS Connection (conn_id='aws_default', conn_type='aws') credentials retrieved from login and password.
[2023-11-07T18:10:28.401+0000] {logging_mixin.py:151} INFO - Error reading file Homework_Assignment_Data.xlsx: 'utf-8' codec can't decode byte 0x9d in position 54: invalid start byte
[2023-11-07T18:10:28.799+0000] {taskinstance.py:1937} ERROR - Task failed with exception
Traceback (most recent call last):
  File "/home/airflow/.local/lib/python3.8/site-packages/airflow/operators/python.py", line 192, in execute
    return_value = self.execute_callable()
  File "/home/airflow/.local/lib/python3.8/site-packages/airflow/operators/python.py", line 209, in execute_callable
    return self.python_callable(*self.op_args, **self.op_kwargs)
  File "/opt/airflow/dags/ps_extract.py", line 85, in extract_s3
    df = pd.read_excel(excel_data, engine='openpyxl')
  File "/home/airflow/.local/lib/python3.8/site-packages/pandas/io/excel/_base.py", line 478, in read_excel
    io = ExcelFile(io, storage_options=storage_options, engine=engine)
  File "/home/airflow/.local/lib/python3.8/site-packages/pandas/io/excel/_base.py", line 1513, in __init__
    self._reader = self._engines[engine](self._io, storage_options=storage_options)
  File "/home/airflow/.local/lib/python3.8/site-packages/pandas/io/excel/_openpyxl.py", line 549, in __init__
    super().__init__(filepath_or_buffer, storage_options=storage_options)
  File "/home/airflow/.local/lib/python3.8/site-packages/pandas/io/excel/_base.py", line 540, in __init__
    self.book = self.load_workbook(self.handles.handle)
  File "/home/airflow/.local/lib/python3.8/site-packages/pandas/io/excel/_openpyxl.py", line 560, in load_workbook
    return load_workbook(
  File "/home/airflow/.local/lib/python3.8/site-packages/openpyxl/reader/excel.py", line 344, in load_workbook
    reader = ExcelReader(filename, read_only, keep_vba,
  File "/home/airflow/.local/lib/python3.8/site-packages/openpyxl/reader/excel.py", line 123, in __init__
    self.archive = _validate_archive(fn)
  File "/home/airflow/.local/lib/python3.8/site-packages/openpyxl/reader/excel.py", line 95, in _validate_archive
    archive = ZipFile(filename, 'r')
  File "/usr/local/lib/python3.8/zipfile.py", line 1269, in __init__
    self._RealGetContents()
  File "/usr/local/lib/python3.8/zipfile.py", line 1336, in _RealGetContents
    raise BadZipFile("File is not a zip file")
zipfile.BadZipFile: File is not a zip file
[2023-11-07T18:10:28.811+0000] {taskinstance.py:1400} INFO - Marking task as FAILED. dag_id=ps_etl_s3, task_id=ps_extract, execution_date=20231107T181024, start_date=20231107T181026, end_date=20231107T181028
[2023-11-07T18:10:28.826+0000] {standard_task_runner.py:104} ERROR - Failed to execute job 154 for task ps_extract (File is not a zip file; 1135)
[2023-11-07T18:10:28.854+0000] {local_task_job_runner.py:228} INFO - Task exited with return code 1
[2023-11-07T18:10:28.900+0000] {taskinstance.py:2778} INFO - 0 downstream tasks scheduled from follow-on schedule check
