[2023-11-04 22:41:40,035] {taskinstance.py:1179} INFO - Dependencies all met for <TaskInstance: read_csv_to_s3.create_local_to_s3_job manual__2023-11-04T22:41:39.170215+00:00 [queued]>
[2023-11-04 22:41:40,045] {taskinstance.py:1179} INFO - Dependencies all met for <TaskInstance: read_csv_to_s3.create_local_to_s3_job manual__2023-11-04T22:41:39.170215+00:00 [queued]>
[2023-11-04 22:41:40,045] {taskinstance.py:1376} INFO - 
--------------------------------------------------------------------------------
[2023-11-04 22:41:40,046] {taskinstance.py:1377} INFO - Starting attempt 1 of 2
[2023-11-04 22:41:40,046] {taskinstance.py:1378} INFO - 
--------------------------------------------------------------------------------
[2023-11-04 22:41:40,058] {taskinstance.py:1397} INFO - Executing <Task(LocalFilesystemToS3Operator): create_local_to_s3_job> on 2023-11-04 22:41:39.170215+00:00
[2023-11-04 22:41:40,062] {standard_task_runner.py:52} INFO - Started process 3212 to run task
[2023-11-04 22:41:40,066] {standard_task_runner.py:79} INFO - Running: ['***', 'tasks', 'run', 'read_csv_to_s3', 'create_local_to_s3_job', 'manual__2023-11-04T22:41:39.170215+00:00', '--job-id', '34', '--raw', '--subdir', 'DAGS_FOLDER/read_csv_to_s3.py', '--cfg-path', '/tmp/tmpswk8trk0', '--error-file', '/tmp/tmpm_2yrlzu']
[2023-11-04 22:41:40,066] {standard_task_runner.py:80} INFO - Job 34: Subtask create_local_to_s3_job
[2023-11-04 22:41:40,147] {task_command.py:371} INFO - Running <TaskInstance: read_csv_to_s3.create_local_to_s3_job manual__2023-11-04T22:41:39.170215+00:00 [running]> on host 9f852cd6fb07
[2023-11-04 22:41:40,221] {taskinstance.py:1591} INFO - Exporting the following env vars:
AIRFLOW_CTX_DAG_OWNER=your_name
AIRFLOW_CTX_DAG_ID=read_csv_to_s3
AIRFLOW_CTX_TASK_ID=create_local_to_s3_job
AIRFLOW_CTX_EXECUTION_DATE=2023-11-04T22:41:39.170215+00:00
AIRFLOW_CTX_TRY_NUMBER=1
AIRFLOW_CTX_DAG_RUN_ID=manual__2023-11-04T22:41:39.170215+00:00
[2023-11-04 22:41:40,233] {base_aws.py:447} WARNING - Unable to use Airflow Connection for credentials.
[2023-11-04 22:41:42,294] {taskinstance.py:1909} ERROR - Task failed with exception
Traceback (most recent call last):
  File "/home/airflow/.local/lib/python3.7/site-packages/airflow/providers/amazon/aws/transfers/local_to_s3.py", line 105, in execute
    self.acl_policy,
  File "/home/airflow/.local/lib/python3.7/site-packages/airflow/providers/amazon/aws/hooks/s3.py", line 63, in wrapper
    return func(*bound_args.args, **bound_args.kwargs)
  File "/home/airflow/.local/lib/python3.7/site-packages/airflow/providers/amazon/aws/hooks/s3.py", line 91, in wrapper
    return func(*bound_args.args, **bound_args.kwargs)
  File "/home/airflow/.local/lib/python3.7/site-packages/airflow/providers/amazon/aws/hooks/s3.py", line 611, in load_file
    client.upload_file(filename, bucket_name, key, ExtraArgs=extra_args, Config=self.transfer_config)
  File "/home/airflow/.local/lib/python3.7/site-packages/boto3/s3/inject.py", line 148, in upload_file
    callback=Callback,
  File "/home/airflow/.local/lib/python3.7/site-packages/boto3/s3/transfer.py", line 288, in upload_file
    future.result()
  File "/home/airflow/.local/lib/python3.7/site-packages/s3transfer/futures.py", line 103, in result
    return self._coordinator.result()
  File "/home/airflow/.local/lib/python3.7/site-packages/s3transfer/futures.py", line 266, in result
    raise self._exception
  File "/home/airflow/.local/lib/python3.7/site-packages/s3transfer/tasks.py", line 269, in _main
    self._submit(transfer_future=transfer_future, **kwargs)
  File "/home/airflow/.local/lib/python3.7/site-packages/s3transfer/upload.py", line 585, in _submit
    upload_input_manager.provide_transfer_size(transfer_future)
  File "/home/airflow/.local/lib/python3.7/site-packages/s3transfer/upload.py", line 244, in provide_transfer_size
    self._osutil.get_file_size(transfer_future.meta.call_args.fileobj)
  File "/home/airflow/.local/lib/python3.7/site-packages/s3transfer/utils.py", line 247, in get_file_size
    return os.path.getsize(filename)
  File "/usr/local/lib/python3.7/genericpath.py", line 50, in getsize
    return os.stat(filename).st_size
FileNotFoundError: [Errno 2] No such file or directory: '/opt/airflow/data/purchases.csv'
[2023-11-04 22:41:42,304] {taskinstance.py:1420} INFO - Marking task as UP_FOR_RETRY. dag_id=read_csv_to_s3, task_id=create_local_to_s3_job, execution_date=20231104T224139, start_date=20231104T224140, end_date=20231104T224142
[2023-11-04 22:41:42,315] {standard_task_runner.py:97} ERROR - Failed to execute job 34 for task create_local_to_s3_job ([Errno 2] No such file or directory: '/opt/airflow/data/purchases.csv'; 3212)
[2023-11-04 22:41:42,331] {local_task_job.py:156} INFO - Task exited with return code 1
[2023-11-04 22:41:42,373] {local_task_job.py:273} INFO - 0 downstream tasks scheduled from follow-on schedule check
