[2023-11-05 23:30:39,600] {taskinstance.py:1179} INFO - Dependencies all met for <TaskInstance: split_excel_to_s3.split_data manual__2023-11-05T23:30:20.567827+00:00 [queued]>
[2023-11-05 23:30:39,613] {taskinstance.py:1179} INFO - Dependencies all met for <TaskInstance: split_excel_to_s3.split_data manual__2023-11-05T23:30:20.567827+00:00 [queued]>
[2023-11-05 23:30:39,614] {taskinstance.py:1376} INFO - 
--------------------------------------------------------------------------------
[2023-11-05 23:30:39,614] {taskinstance.py:1377} INFO - Starting attempt 1 of 1
[2023-11-05 23:30:39,615] {taskinstance.py:1378} INFO - 
--------------------------------------------------------------------------------
[2023-11-05 23:30:39,631] {taskinstance.py:1397} INFO - Executing <Task(PythonOperator): split_data> on 2023-11-05 23:30:20.567827+00:00
[2023-11-05 23:30:39,638] {standard_task_runner.py:52} INFO - Started process 1079 to run task
[2023-11-05 23:30:39,642] {standard_task_runner.py:79} INFO - Running: ['***', 'tasks', 'run', 'split_excel_to_s3', 'split_data', 'manual__2023-11-05T23:30:20.567827+00:00', '--job-id', '59', '--raw', '--subdir', 'DAGS_FOLDER/write_xlsx_to_csv_s3.py', '--cfg-path', '/tmp/tmpensd2sum', '--error-file', '/tmp/tmpeg7lm9od']
[2023-11-05 23:30:39,645] {standard_task_runner.py:80} INFO - Job 59: Subtask split_data
[2023-11-05 23:30:39,745] {task_command.py:371} INFO - Running <TaskInstance: split_excel_to_s3.split_data manual__2023-11-05T23:30:20.567827+00:00 [running]> on host 59b74f6ac638
[2023-11-05 23:30:39,840] {taskinstance.py:1591} INFO - Exporting the following env vars:
AIRFLOW_CTX_DAG_OWNER=***
AIRFLOW_CTX_DAG_ID=split_excel_to_s3
AIRFLOW_CTX_TASK_ID=split_data
AIRFLOW_CTX_EXECUTION_DATE=2023-11-05T23:30:20.567827+00:00
AIRFLOW_CTX_TRY_NUMBER=1
AIRFLOW_CTX_DAG_RUN_ID=manual__2023-11-05T23:30:20.567827+00:00
[2023-11-05 23:30:39,878] {taskinstance.py:1909} ERROR - Task failed with exception
Traceback (most recent call last):
  File "/home/airflow/.local/lib/python3.7/site-packages/pandas/core/indexes/base.py", line 3361, in get_loc
    return self._engine.get_loc(casted_key)
  File "pandas/_libs/index.pyx", line 76, in pandas._libs.index.IndexEngine.get_loc
  File "pandas/_libs/index.pyx", line 108, in pandas._libs.index.IndexEngine.get_loc
  File "pandas/_libs/hashtable_class_helper.pxi", line 5198, in pandas._libs.hashtable.PyObjectHashTable.get_item
  File "pandas/_libs/hashtable_class_helper.pxi", line 5206, in pandas._libs.hashtable.PyObjectHashTable.get_item
KeyError: 'column_name'

The above exception was the direct cause of the following exception:

Traceback (most recent call last):
  File "/home/airflow/.local/lib/python3.7/site-packages/airflow/operators/python.py", line 171, in execute
    return_value = self.execute_callable()
  File "/home/airflow/.local/lib/python3.7/site-packages/airflow/operators/python.py", line 189, in execute_callable
    return self.python_callable(*self.op_args, **self.op_kwargs)
  File "/opt/airflow/dags/write_xlsx_to_csv_s3.py", line 48, in split_data
    df1 = df[df['column_name'] == 'criteria_1']
  File "/home/airflow/.local/lib/python3.7/site-packages/pandas/core/frame.py", line 3458, in __getitem__
    indexer = self.columns.get_loc(key)
  File "/home/airflow/.local/lib/python3.7/site-packages/pandas/core/indexes/base.py", line 3363, in get_loc
    raise KeyError(key) from err
KeyError: 'column_name'
[2023-11-05 23:30:39,893] {taskinstance.py:1420} INFO - Marking task as FAILED. dag_id=split_excel_to_s3, task_id=split_data, execution_date=20231105T233020, start_date=20231105T233039, end_date=20231105T233039
[2023-11-05 23:30:39,906] {standard_task_runner.py:97} ERROR - Failed to execute job 59 for task split_data ('column_name'; 1079)
[2023-11-05 23:30:39,935] {local_task_job.py:156} INFO - Task exited with return code 1
[2023-11-05 23:30:39,993] {local_task_job.py:273} INFO - 0 downstream tasks scheduled from follow-on schedule check
