[2023-11-04 22:47:06,039] {taskinstance.py:1179} INFO - Dependencies all met for <TaskInstance: read_csv_to_s3.create_local_to_s3_job manual__2023-11-04T22:47:05.054987+00:00 [queued]>
[2023-11-04 22:47:06,053] {taskinstance.py:1179} INFO - Dependencies all met for <TaskInstance: read_csv_to_s3.create_local_to_s3_job manual__2023-11-04T22:47:05.054987+00:00 [queued]>
[2023-11-04 22:47:06,054] {taskinstance.py:1376} INFO - 
--------------------------------------------------------------------------------
[2023-11-04 22:47:06,054] {taskinstance.py:1377} INFO - Starting attempt 1 of 2
[2023-11-04 22:47:06,055] {taskinstance.py:1378} INFO - 
--------------------------------------------------------------------------------
[2023-11-04 22:47:06,071] {taskinstance.py:1397} INFO - Executing <Task(LocalFilesystemToS3Operator): create_local_to_s3_job> on 2023-11-04 22:47:05.054987+00:00
[2023-11-04 22:47:06,075] {standard_task_runner.py:52} INFO - Started process 247 to run task
[2023-11-04 22:47:06,078] {standard_task_runner.py:79} INFO - Running: ['***', 'tasks', 'run', 'read_csv_to_s3', 'create_local_to_s3_job', 'manual__2023-11-04T22:47:05.054987+00:00', '--job-id', '38', '--raw', '--subdir', 'DAGS_FOLDER/read_csv_to_s3.py', '--cfg-path', '/tmp/tmp62m9_j6a', '--error-file', '/tmp/tmpdmtsjkem']
[2023-11-04 22:47:06,079] {standard_task_runner.py:80} INFO - Job 38: Subtask create_local_to_s3_job
[2023-11-04 22:47:06,141] {task_command.py:371} INFO - Running <TaskInstance: read_csv_to_s3.create_local_to_s3_job manual__2023-11-04T22:47:05.054987+00:00 [running]> on host 0ba15ff5e7b4
[2023-11-04 22:47:06,212] {taskinstance.py:1591} INFO - Exporting the following env vars:
AIRFLOW_CTX_DAG_OWNER=your_name
AIRFLOW_CTX_DAG_ID=read_csv_to_s3
AIRFLOW_CTX_TASK_ID=create_local_to_s3_job
AIRFLOW_CTX_EXECUTION_DATE=2023-11-04T22:47:05.054987+00:00
AIRFLOW_CTX_TRY_NUMBER=1
AIRFLOW_CTX_DAG_RUN_ID=manual__2023-11-04T22:47:05.054987+00:00
[2023-11-04 22:47:06,223] {base.py:68} INFO - Using connection ID 'aws_akanksha' for task execution.
[2023-11-04 22:47:06,224] {base_aws.py:206} INFO - Credentials retrieved from login
[2023-11-04 22:47:06,753] {taskinstance.py:1909} ERROR - Task failed with exception
Traceback (most recent call last):
  File "/home/airflow/.local/lib/python3.7/site-packages/boto3/s3/transfer.py", line 288, in upload_file
    future.result()
  File "/home/airflow/.local/lib/python3.7/site-packages/s3transfer/futures.py", line 103, in result
    return self._coordinator.result()
  File "/home/airflow/.local/lib/python3.7/site-packages/s3transfer/futures.py", line 266, in result
    raise self._exception
  File "/home/airflow/.local/lib/python3.7/site-packages/s3transfer/tasks.py", line 139, in __call__
    return self._execute_main(kwargs)
  File "/home/airflow/.local/lib/python3.7/site-packages/s3transfer/tasks.py", line 162, in _execute_main
    return_value = self._main(**kwargs)
  File "/home/airflow/.local/lib/python3.7/site-packages/s3transfer/upload.py", line 758, in _main
    client.put_object(Bucket=bucket, Key=key, Body=body, **extra_args)
  File "/home/airflow/.local/lib/python3.7/site-packages/botocore/client.py", line 508, in _api_call
    return self._make_api_call(operation_name, kwargs)
  File "/home/airflow/.local/lib/python3.7/site-packages/botocore/client.py", line 915, in _make_api_call
    raise error_class(parsed_response, operation_name)
botocore.exceptions.ClientError: An error occurred (AccessDenied) when calling the PutObject operation: Access Denied

During handling of the above exception, another exception occurred:

Traceback (most recent call last):
  File "/home/airflow/.local/lib/python3.7/site-packages/airflow/providers/amazon/aws/transfers/local_to_s3.py", line 105, in execute
    self.acl_policy,
  File "/home/airflow/.local/lib/python3.7/site-packages/airflow/providers/amazon/aws/hooks/s3.py", line 63, in wrapper
    return func(*bound_args.args, **bound_args.kwargs)
  File "/home/airflow/.local/lib/python3.7/site-packages/airflow/providers/amazon/aws/hooks/s3.py", line 91, in wrapper
    return func(*bound_args.args, **bound_args.kwargs)
  File "/home/airflow/.local/lib/python3.7/site-packages/airflow/providers/amazon/aws/hooks/s3.py", line 611, in load_file
    client.upload_file(filename, bucket_name, key, ExtraArgs=extra_args, Config=self.transfer_config)
  File "/home/airflow/.local/lib/python3.7/site-packages/boto3/s3/inject.py", line 148, in upload_file
    callback=Callback,
  File "/home/airflow/.local/lib/python3.7/site-packages/boto3/s3/transfer.py", line 296, in upload_file
    filename, '/'.join([bucket, key]), e
boto3.exceptions.S3UploadFailedError: Failed to upload /opt/***/data/purchases.csv to playstudios-assignment/purchases.csv: An error occurred (AccessDenied) when calling the PutObject operation: Access Denied
[2023-11-04 22:47:06,764] {taskinstance.py:1420} INFO - Marking task as UP_FOR_RETRY. dag_id=read_csv_to_s3, task_id=create_local_to_s3_job, execution_date=20231104T224705, start_date=20231104T224706, end_date=20231104T224706
[2023-11-04 22:47:06,777] {standard_task_runner.py:97} ERROR - Failed to execute job 38 for task create_local_to_s3_job (Failed to upload /opt/***/data/purchases.csv to playstudios-assignment/purchases.csv: An error occurred (AccessDenied) when calling the PutObject operation: Access Denied; 247)
[2023-11-04 22:47:06,814] {local_task_job.py:156} INFO - Task exited with return code 1
[2023-11-04 22:47:06,845] {local_task_job.py:273} INFO - 0 downstream tasks scheduled from follow-on schedule check
