[2023-11-07T17:26:21.131+0000] {taskinstance.py:1159} INFO - Dependencies all met for dep_context=non-requeueable deps ti=<TaskInstance: ps_etl_s3.ps_extract manual__2023-11-07T17:26:19.158324+00:00 [queued]>
[2023-11-07T17:26:21.140+0000] {taskinstance.py:1159} INFO - Dependencies all met for dep_context=requeueable deps ti=<TaskInstance: ps_etl_s3.ps_extract manual__2023-11-07T17:26:19.158324+00:00 [queued]>
[2023-11-07T17:26:21.140+0000] {taskinstance.py:1361} INFO - Starting attempt 1 of 1
[2023-11-07T17:26:21.184+0000] {taskinstance.py:1382} INFO - Executing <Task(PythonOperator): ps_extract> on 2023-11-07 17:26:19.158324+00:00
[2023-11-07T17:26:21.189+0000] {standard_task_runner.py:57} INFO - Started process 570 to run task
[2023-11-07T17:26:21.193+0000] {standard_task_runner.py:84} INFO - Running: ['***', 'tasks', 'run', 'ps_etl_s3', 'ps_extract', 'manual__2023-11-07T17:26:19.158324+00:00', '--job-id', '145', '--raw', '--subdir', 'DAGS_FOLDER/ps_etl_s3_input.py', '--cfg-path', '/tmp/tmp2lmc_lvl']
[2023-11-07T17:26:21.196+0000] {standard_task_runner.py:85} INFO - Job 145: Subtask ps_extract
[2023-11-07T17:26:21.240+0000] {task_command.py:416} INFO - Running <TaskInstance: ps_etl_s3.ps_extract manual__2023-11-07T17:26:19.158324+00:00 [running]> on host 19429b98c313
[2023-11-07T17:26:21.309+0000] {taskinstance.py:1662} INFO - Exporting env vars: AIRFLOW_CTX_DAG_OWNER='***' AIRFLOW_CTX_DAG_ID='ps_etl_s3' AIRFLOW_CTX_TASK_ID='ps_extract' AIRFLOW_CTX_EXECUTION_DATE='2023-11-07T17:26:19.158324+00:00' AIRFLOW_CTX_TRY_NUMBER='1' AIRFLOW_CTX_DAG_RUN_ID='manual__2023-11-07T17:26:19.158324+00:00'
[2023-11-07T17:26:21.318+0000] {base.py:73} INFO - Using connection ID 'aws_default' for task execution.
[2023-11-07T17:26:21.319+0000] {connection_wrapper.py:340} INFO - AWS Connection (conn_id='aws_default', conn_type='aws') credentials retrieved from login and password.
[2023-11-07T17:26:22.840+0000] {taskinstance.py:1937} ERROR - Task failed with exception
Traceback (most recent call last):
  File "/home/airflow/.local/lib/python3.8/site-packages/airflow/operators/python.py", line 192, in execute
    return_value = self.execute_callable()
  File "/home/airflow/.local/lib/python3.8/site-packages/airflow/operators/python.py", line 209, in execute_callable
    return self.python_callable(*self.op_args, **self.op_kwargs)
  File "/opt/airflow/dags/ps_extract.py", line 77, in extract_s3
    file_content = s3_hook.read_key(key=file_key, bucket_name=bucket_name)
  File "/home/airflow/.local/lib/python3.8/site-packages/airflow/providers/amazon/aws/hooks/s3.py", line 136, in wrapper
    return func(*bound_args.args, **bound_args.kwargs)
  File "/home/airflow/.local/lib/python3.8/site-packages/airflow/providers/amazon/aws/hooks/s3.py", line 90, in wrapper
    return func(*bound_args.args, **bound_args.kwargs)
  File "/home/airflow/.local/lib/python3.8/site-packages/airflow/providers/amazon/aws/hooks/s3.py", line 939, in read_key
    return obj.get()["Body"].read().decode("utf-8")
UnicodeDecodeError: 'utf-8' codec can't decode byte 0x9d in position 54: invalid start byte
[2023-11-07T17:26:22.849+0000] {taskinstance.py:1400} INFO - Marking task as FAILED. dag_id=ps_etl_s3, task_id=ps_extract, execution_date=20231107T172619, start_date=20231107T172621, end_date=20231107T172622
[2023-11-07T17:26:22.859+0000] {standard_task_runner.py:104} ERROR - Failed to execute job 145 for task ps_extract ('utf-8' codec can't decode byte 0x9d in position 54: invalid start byte; 570)
[2023-11-07T17:26:22.896+0000] {local_task_job_runner.py:228} INFO - Task exited with return code 1
[2023-11-07T17:26:22.928+0000] {taskinstance.py:2778} INFO - 0 downstream tasks scheduled from follow-on schedule check
